Workbook

Sheet Dashboard
B2: Business Sales Performance Analysis & Decision Dashboard
B3: Maincrafts Technology | Prepared by: Business Analytics Intern | Data period: Jan–Dec 2024
B5: Total Revenue | E5: Total Profit | H5: Avg Profit Margin | K5: Total Orders
B7: =SUM(Cleaned_Data!$I$2:$I$315) -> 6848966.7 | E7: =SUM(Cleaned_Data!$G$2:$G$315) -> 1142001.6 | H7: =SUM(Cleaned_Data!$G$2:$G$315)/SUM(Cleaned_Data!$I$2:$I$315) -> 0.16674072 | K7: =COUNTA(Cleaned_Data!$H$2:$H$315) -> 314
B11: Best Performing Region: | D11: =INDEX(Sales_by_Region!A2:A6,MATCH(MAX(Sales_by_Region!B2:B6),Sales_by_Region!B2:B6,0)) -> North
B12: Top Product: | D12: =INDEX(Sales_by_Product!A2:A17,MATCH(MAX(Sales_by_Product!B2:B17),Sales_by_Product!B2:B17,0)) -> Office Chair

Sheet Raw_Data
A1: Order_ID | B1: Order_Date | C1: Region | D1: Product | E1: Category | F1: Sales_Amount | G1: Profit | H1: Quantity
A2: 1014 | B2: 2024-07-04 | C2: West | D2: Whiteboard | E2: Stationery | F2: 598.53 | G2: 545.06 | H2: 4
A3: 1158 | B3: 2024-09-09 | C3: East | D3: Wireless Mouse | E3: Electronics | F3: 1159.61 | G3: 607.55 | H3: 2
A4: 1007 | B4: 2024-12-26 | C4: South | D4: Sticky Notes | E4: Stationery | F4: 75.2 | G4: 36.94 | H4: 2
A5: 1250 | B5: 2024-12-30 | C5: South | D5: Sticky Notes | E5: Stationery | F5: 560.03 | G5: 2201.19 | H5: 12
A6: 1064 | B6: 2024-12-06 | C6: West | D6: Standing Desk | E6: Furniture | F6: 8934.52 | G6: 11778.88 | H6: 7
A7: 1046 | B7: 2024-05-15 | C7: South | D7: Notebook Pack | E7: Stationery | F7: 539.34 | G7: 375.9 | H7: 2
A8: 1204 | B8: 2024-02-01 | C8: South | D8: Electric Kettle | E8: Appliances | F8: 1645.06 | G8: 2736 | H8: 8
A9: 1186 | B9: 2024-12-11 | C9: North | D9: Standing Desk | E9: Furniture | F9: 5084.98 | G9: 1621.42 | H9: 2
A10: 1269 | B10: 2024-05-24 | C10: North | D10: Notebook Pack | E10: Stationery | F10: 378.64 | G10: 1116.44 | H10: 8
A11: 1283 | B11: 2024-12-27 | C11: North | D11: Electric Kettle | E11: Appliances | F11: 3430.34 | G11: 1721.75 | H11: 3
A12: 1069 | B12: 2024-08-21 | C12: North | D12: Electric Kettle | E12: Appliances | F12: 5010.39 | G12: 5930.12 | H12: 7
A13: 1015 | B13: 2024-02-26 | C13: North | D13: Coffee Maker | E13: Appliances | F13: 3898.02 | G13: 2280.92 | H13: 3
... A122: 1107 | B122: 2024-10-12 | C122: North | D122: Bluetooth Speaker | E122: Electronics | F122: 3043.38 | G122: 5251.75 | H122: 7
A123: 1257 | B123: 2024-02-10 | D123: Bookshelf | E123: Furniture | F123: 4364.87 | G123: 4250.56 | H123: 5
A124: 1102 | B124: 2024-02-21 | C124: East | D124: Desk Fan | E124: Appliances | F124: 2473.86 | G124: 1418.07 | H124: 4
A125: 1170 | B125: 2024-08-19 | C125: North | D125: Desk Fan | E125: Appliances | F125: 2152.66 | G125: 3367.44 | H125: 9
A126: 1020 | B126: 2024-03-23 | C126: East | D126: Standing Desk | E126: Furniture | F126: 11558.25 | G126: 19836.6 | H126: 9
A127: 1179 | B127: 2024-01-27 | C127: West | D127: Desk Fan | E127: Appliances | F127: 3781.76 | G127: 2688.78 | H127: 5
A128: 1118 | B128: 2024-03-30 | C128: North | D128: USB-C Hub | E128: Electronics | F128: 2720.17 | G128: 4151.13 | H128: 8
A129: 1306 | B129: 2024-05-06 | C129: South | D129: Electric Kettle | E129: Appliances | F129: 4445.38 | G129: 10013.39 | H129: 11
A130: 1049 | B130: 2024-03-07 | C130: East | D130: Wireless Mouse | E130: Electronics | F130: 4425.25 | G130: 7099.8 | H130: 11
A131: 1291 | B131: 2024-02-21 | C131: North | D131: Standing Desk | E131: Furniture | F131: 5637.79 | G131: 5394.35 | H131: 7
A132: 1207 | B132: 2024-06-17 | C132: North | D132: USB-C Hub | E132: Electronics | F132: 2864.46 | G132: 1041.81 | H132: 2
A133: 1246 | B133: 2024-04-05 | C133: North | D133: Office Chair | E133: Furniture | F133: 7418.58 | G133: 11253.99 | H133: 8
A134: 1117 | B134: 2024-02-16 | C134: North | D134: Sticky Notes | E134: Stationery | F134: 579.05 | G134: 850.49 | H134: 4
A135: 1288 | B135: 2024-05-28 | C135: South | D135: Desk Fan | E135: Appliances | F135: 2436.81 | G135: 452.51 | H135: 1
A136: 1178 | B136: 2024-10-27 | C136: North | D136: Pen Set | E136: Stationery | F136: 358.93 | G136: 1078.95 | H136: 9
A137: 1316 | B137: 2024-06-01 | C137: North | D137: Office Chair | E137: Furniture | F137: 8898.25 | G137: 10345.71
A138: 1009 | B138: 2024-06-30 | C138: East | D138: Pen Set | E138: Stationery | F138: 418.6 | G138: 569.91 | H138: 4
A139: 1112 | B139: 2024-05-15 | C139: South | D139: Coffee Maker | E139: Appliances | F139: 3736.1 | G139: 8074.29 | H139: 11
A140: 1240 | B140: 2024-03-26 | C140: West | D140: Electric Kettle | E140: Appliances | F140: 3108.81 | G140: 5732.23 | H140: 12
A141: 1111 | B141: 2024-04-28 | C141: North | D141: Desk Fan | E141: Appliances | F141: 4239.91 | G141: 3908.32 | H141: 5
A142: 1119 | B142: 2024-11-21 | C142: West | D142: Pen Set | E142: Stationery | F142: 582.98 | G142: 1371.18 | H142: 8
A143: 1308 | B143: 2024-10-20 | C143: South | D143: Wireless Mouse | E143: Electronics | F143: 1354.45 | G143: 2102.77 | H143: 9
A144: 1167 | B144: 2024-10-03 | C144: South | D144: Pen Set | E144: Stationery | F144: 489.18 | G144: 542.95 | H144: 5
A145: 1024 | B145: 2024-10-03 | C145: South | D145: Whiteboard | E145: Stationery | F145: 429.43 | G145: 1765.42 | H145: 12
A146: 1176 | B146: 2024-06-09 | C146: North | D146: Electric Kettle | E146: Appliances | F146: 2543.85 | G146: 2325.35 | H146: 7
A147: 1254 | B147: 2024-11-24 | C147: East | D147: Bluetooth Speaker | E147: Electronics | F147: 2464.91 | G147: 1128.03 | H147: 2
A148: 1091 | B148: 2024-01-07 | C148: East | D148: Notebook Pack | E148: Stationery | F148: 502.28 | G148: 777.41 | H148: 7
...

Sheet Cleaned_Data
A1: Order_ID | B1: Order_Date | C1: Region | D1: Product | E1: Category | F1: Sales_Amount | G1: Profit | H1: Quantity | I1: Total_Sales | J1: Profit_Margin
A2: 1035 | B2: 45293 | C2: West | D2: Bluetooth Speaker | E2: Electronics | F2: 1781.25 | G2: 3060.47 | H2: 7 | I2: =F2*H2 -> 12468.75 | J2: =IF(I2=0,0,G2/I2) -> 0.24545123
A3: 1104 | B3: 45298 | C3: North | D3: Filing Cabinet | E3: Furniture | F3: 5201.22 | G3: 7148.85 | H3: 10 | I3: =F3*H3 -> 52012.2 | J3: =IF(I3=0,0,G3/I3) -> 0.13744564
A4: 1091 | B4: 45298 | C4: East | D4: Notebook Pack | E4: Stationery | F4: 502.28 | G4: 777.41 | H4: 7 | I4: =F4*H4 -> 3515.96 | J4: =IF(I4=0,0,G4/I4) -> 0.22110889
A5: 1211 | B5: 45301 | C5: East | D5: Laptop Stand | E5: Electronics | F5: 1942.8 | G5: 3172.83 | H5: 6 | I5: =F5*H5 -> 11656.8 | J5: =IF(I5=0,0,G5/I5) -> 0.27218705
A6: 1086 | B6: 45302 | C6: South | D6: Bluetooth Speaker | E6: Electronics | F6: 1363.81 | G6: 1912 | H6: 10 | I6: =F6*H6 -> 13638.1 | J6: =IF(I6=0,0,G6/I6) -> 0.14019548
A7: 1156 | B7: 45304 | C7: West | D7: Bluetooth Speaker | E7: Electronics | F7: 4071.67 | G7: 8543.39 | H7: 10 | I7: =F7*H7 -> 40716.7 | J7: =IF(I7=0,0,G7/I7) -> 0.20982521
A8: 1182 | B8: 45306 | C8: East | D8: Webcam HD | E8: Electronics | F8: 1811.1 | G8: 1314.78 | H8: 3 | I8: =F8*H8 -> 5433.3 | J8: =IF(I8=0,0,G8/I8) -> 0.24198553
A9: 1313 | B9: 45308 | C9: West | D9: Wireless Mouse | E9: Electronics | F9: 2312.81 | G9: 2810.48 | H9: 5 | I9: =F9*H9 -> 11564.05 | J9: =IF(I9=0,0,G9/I9) -> 0.24303596
A10: 1281 | B10: 45308 | C10: South | D10: Coffee Maker | E10: Appliances | F10: 5277.28 | G10: 5973.22 | H10: 10 | I10: =F10*H10 -> 52772.8 | J10: =IF(I10=0,0,G10/I10) -> 0.11318748
A11: 1002 | B11: 45308 | C11: West | D11: Webcam HD | E11: Electronics | F11: 1146.67 | G11: 180.29 | H11: 1 | I11: =F11*H11 -> 1146.67 | J11: =IF(I11=0,0,G11/I11) -> 0.15722919
A12: 1295 | B12: 45310 | C12: South | D12: Filing Cabinet | E12: Furniture | F12: 9985.63 | G12: 7154.72 | H12: 7 | I12: =F12*H12 -> 69899.41 | J12: =IF(I12=0,0,G12/I12) -> 0.10235737
A13: 1205 | B13: 45312 | C13: South | D13: Notebook Pack | E13: Stationery | F13: 439.19 | G13: 699.54 | H13: 4 | I13: =F13*H13 -> 1756.76 | J13: =IF(I13=0,0,G13/I13) -> 0.39819896
... A315: 1223 | B315: 45657 | C315: North | D315: USB-C Hub | E315: Electronics | F315: 2040.57 | G315: 3218.07 | H315: 11 | I315: =F315*H315 -> 22446.27 | J315: =IF(I315=0,0,G315/I315) -> 0.1433677

Sheet Sales_by_Region
A1: Region | B1: Total Sales | C1: Total Profit | D1: Order Count
A2: East | B2: =SUMIF(Cleaned_Data!$C$2:$C$315,A2,Cleaned_Data!$I$2:$I$315) -> 1772409.1 | C2: =SUMIF(Cleaned_Data!$C$2:$C$315,A2,Cleaned_Data!$G$2:$G$315) -> 283781.87 | D2: =COUNTIF(Cleaned_Data!$C$2:$C$315,A2) -> 69
A3: North | B3: =SUMIF(Cleaned_Data!$C$2:$C$315,A3,Cleaned_Data!$I$2:$I$315) -> 1813985 | C3: =SUMIF(Cleaned_Data!$C$2:$C$315,A3,Cleaned_Data!$G$2:$G$315) -> 297072.02 | D3: =COUNTIF(Cleaned_Data!$C$2:$C$315,A3) -> 88
A4: South | B4: =SUMIF(Cleaned_Data!$C$2:$C$315,A4,Cleaned_Data!$I$2:$I$315) -> 1608310.8 | C4: =SUMIF(Cleaned_Data!$C$2:$C$315,A4,Cleaned_Data!$G$2:$G$315) -> 277412.26 | D4: =COUNTIF(Cleaned_Data!$C$2:$C$315,A4) -> 77
A5: Unspecified | B5: =SUMIF(Cleaned_Data!$C$2:$C$315,A5,Cleaned_Data!$I$2:$I$315) -> 23244.58 | C5: =SUMIF(Cleaned_Data!$C$2:$C$315,A5,Cleaned_Data!$G$2:$G$315) -> 4715.17 | D5: =COUNTIF(Cleaned_Data!$C$2:$C$315,A5) -> 2
A6: West | B6: =SUMIF(Cleaned_Data!$C$2:$C$315,A6,Cleaned_Data!$I$2:$I$315) -> 1631017.1 | C6: =SUMIF(Cleaned_Data!$C$2:$C$315,A6,Cleaned_Data!$G$2:$G$315) -> 279020.33 | D6: =COUNTIF(Cleaned_Data!$C$2:$C$315,A6) -> 78

Sheet Sales_by_Product
A1: Product | B1: Total Sales | C1: Units Sold
A2: Office Chair | B2: =SUMIF(Cleaned_Data!$D$2:$D$315,A2,Cleaned_Data!$I$2:$I$315) -> 1023261 | C2: =SUMIF(Cleaned_Data!$D$2:$D$315,A2,Cleaned_Data!$H$2:$H$315) -> 125
A3: Bookshelf | B3: =SUMIF(Cleaned_Data!$D$2:$D$315,A3,Cleaned_Data!$I$2:$I$315) -> 921004.07 | C3: =SUMIF(Cleaned_Data!$D$2:$D$315,A3,Cleaned_Data!$H$2:$H$315) -> 127
A4: Filing Cabinet | B4: =SUMIF(Cleaned_Data!$D$2:$D$315,A4,Cleaned_Data!$I$2:$I$315) -> 841772.92 | C4: =SUMIF(Cleaned_Data!$D$2:$D$315,A4,Cleaned_Data!$H$2:$H$315) -> 106
A5: Coffee Maker | B5: =SUMIF(Cleaned_Data!$D$2:$D$315,A5,Cleaned_Data!$I$2:$I$315) -> 818510.19 | C5: =SUMIF(Cleaned_Data!$D$2:$D$315,A5,Cleaned_Data!$H$2:$H$315) -> 222
A6: Desk Fan | B6: =SUMIF(Cleaned_Data!$D$2:$D$315,A6,Cleaned_Data!$I$2:$I$315) -> 671777.13 | C6: =SUMIF(Cleaned_Data!$D$2:$D$315,A6,Cleaned_Data!$H$2:$H$315) -> 197
A7: Standing Desk | B7: =SUMIF(Cleaned_Data!$D$2:$D$315,A7,Cleaned_Data!$I$2:$I$315) -> 510827.62 | C7: =SUMIF(Cleaned_Data!$D$2:$D$315,A7,Cleaned_Data!$H$2:$H$315) -> 70
A8: Electric Kettle | B8: =SUMIF(Cleaned_Data!$D$2:$D$315,A8,Cleaned_Data!$I$2:$I$315) -> 416449.13 | C8: =SUMIF(Cleaned_Data!$D$2:$D$315,A8,Cleaned_Data!$H$2:$H$315) -> 135
A9: USB-C Hub | B9: =SUMIF(Cleaned_Data!$D$2:$D$315,A9,Cleaned_Data!$I$2:$I$315) -> 382064.64 | C9: =SUMIF(Cleaned_Data!$D$2:$D$315,A9,Cleaned_Data!$H$2:$H$315) -> 128
A10: Webcam HD | B10: =SUMIF(Cleaned_Data!$D$2:$D$315,A10,Cleaned_Data!$I$2:$I$315) -> 351983.62 | C10: =SUMIF(Cleaned_Data!$D$2:$D$315,A10,Cleaned_Data!$H$2:$H$315) -> 124
A11: Bluetooth Speaker | B11: =SUMIF(Cleaned_Data!$D$2:$D$315,A11,Cleaned_Data!$I$2:$I$315) -> 258554.67 | C11: =SUMIF(Cleaned_Data!$D$2:$D$315,A11,Cleaned_Data!$H$2:$H$315) -> 93
A12: Laptop Stand | B12: =SUMIF(Cleaned_Data!$D$2:$D$315,A12,Cleaned_Data!$I$2:$I$315) -> 254113.86 | C12: =SUMIF(Cleaned_Data!$D$2:$D$315,A12,Cleaned_Data!$H$2:$H$315) -> 109
A13: Wireless Mouse | B13: =SUMIF(Cleaned_Data!$D$2:$D$315,A13,Cleaned_Data!$I$2:$I$315) -> 194057.81 | C13: =SUMIF(Cleaned_Data!$D$2:$D$315,A13,Cleaned_Data!$H$2:$H$315) -> 61
... A17: Notebook Pack | B17: =SUMIF(Cleaned_Data!$D$2:$D$315,A17,Cleaned_Data!$I$2:$I$315) -> 42874.53 | C17: =SUMIF(Cleaned_Data!$D$2:$D$315,A17,Cleaned_Data!$H$2:$H$315) -> 136

Sheet Monthly_Trend
A1: Month | B1: Total Sales | C1: Total Profit
A2: 2024-01 | B2: =SUMPRODUCT((Cleaned_Data!$B$2:$B$315>=DATE(2024,1,1))*(Cleaned_Data!$B$2:$B$315<EDATE(DATE(2024,1,1),1))*Cleaned_Data!$I$2:$I$315) -> 521489.48 | C2: =SUMPRODUCT((Cleaned_Data!$B$2:$B$315>=DATE(2024,1,1))*(Cleaned_Data!$B$2:$B$315<EDATE(DATE(2024,1,1),1))*Cleaned_Data!$G$2:$G$315) -> 83460.75
A3: 2024-02 | B3: =SUMPRODUCT((Cleaned_Data!$B$2:$B$315>=DATE(2024,2,1))*(Cleaned_Data!$B$2:$B$315<EDATE(DATE(2024,2,1),1))*Cleaned_Data!$I$2:$I$315) -> 666935.03 | C3: =SUMPRODUCT((Cleaned_Data!$B$2:$B$315>=DATE(2024,2,1))*(Cleaned_Data!$B$2:$B$315<EDATE(DATE(2024,2,1),1))*Cleaned_Data!$G$2:$G$315) -> 107896.38
A4: 2024-03 | B4: =SUMPRODUCT((Cleaned_Data!$B$2:$B$315>=DATE(2024,3,1))*(Cleaned_Data!$B$2:$B$315<EDATE(DATE(2024,3,1),1))*Cleaned_Data!$I$2:$I$315) -> 818423.81 | C4: =SUMPRODUCT((Cleaned_Data!$B$2:$B$315>=DATE(2024,3,1))*(Cleaned_Data!$B$2:$B$315<EDATE(DATE(2024,3,1),1))*Cleaned_Data!$G$2:$G$315) -> 140532.23
A5: 2024-04 | B5: =SUMPRODUCT((Cleaned_Data!$B$2:$B$315>=DATE(2024,4,1))*(Cleaned_Data!$B$2:$B$315<EDATE(DATE(2024,4,1),1))*Cleaned_Data!$I$2:$I$315) -> 557807.41 | C5: =SUMPRODUCT((Cleaned_Data!$B$2:$B$315>=DATE(2024,4,1))*(Cleaned_Data!$B$2:$B$315<EDATE(DATE(2024,4,1),1))*Cleaned_Data!$G$2:$G$315) -> 86523.54
A6: 2024-05 | B6: =SUMPRODUCT((Cleaned_Data!$B$2:$B$315>=DATE(2024,5,1))*(Cleaned_Data!$B$2:$B$315<EDATE(DATE(2024,5,1),1))*Cleaned_Data!$I$2:$I$315) -> 545263.57 | C6: =SUMPRODUCT((Cleaned_Data!$B$2:$B$315>=DATE(2024,5,1))*(Cleaned_Data!$B$2:$B$315<EDATE(DATE(2024,5,1),1))*Cleaned_Data!$G$2:$G$315) -> 93486.33
A7: 2024-06 | B7: =SUMPRODUCT((Cleaned_Data!$B$2:$B$315>=DATE(2024,6,1))*(Cleaned_Data!$B$2:$B$315<EDATE(DATE(2024,6,1),1))*Cleaned_Data!$I$2:$I$315) -> 474574.1 | C7: =SUMPRODUCT((Cleaned_Data!$B$2:$B$315>=DATE(2024,6,1))*(Cleaned_Data!$B$2:$B$315<EDATE(DATE(2024,6,1),1))*Cleaned_Data!$G$2:$G$315) -> 85900.74
A8: 2024-07 | B8: =SUMPRODUCT((Cleaned_Data!$B$2:$B$315>=DATE(2024,7,1))*(Cleaned_Data!$B$2:$B$315<EDATE(DATE(2024,7,1),1))*Cleaned_Data!$I$2:$I$315) -> 780536.15 | C8: =SUMPRODUCT((Cleaned_Data!$B$2:$B$315>=DATE(2024,7,1))*(Cleaned_Data!$B$2:$B$315<EDATE(DATE(2024,7,1),1))*Cleaned_Data!$G$2:$G$315) -> 119042.5
A9: 2024-08 | B9: =SUMPRODUCT((Cleaned_Data!$B$2:$B$315>=DATE(2024,8,1))*(Cleaned_Data!$B$2:$B$315<EDATE(DATE(2024,8,1),1))*Cleaned_Data!$I$2:$I$315) -> 642044.75 | C9: =SUMPRODUCT((Cleaned_Data!$B$2:$B$315>=DATE(2024,8,1))*(Cleaned_Data!$B$2:$B$315<EDATE(DATE(2024,8,1),1))*Cleaned_Data!$G$2:$G$315) -> 107603.91
A10: 2024-09 | B10: =SUMPRODUCT((Cleaned_Data!$B$2:$B$315>=DATE(2024,9,1))*(Cleaned_Data!$B$2:$B$315<EDATE(DATE(2024,9,1),1))*Cleaned_Data!$I$2:$I$315) -> 392852.04 | C10: =SUMPRODUCT((Cleaned_Data!$B$2:$B$315>=DATE(2024,9,1))*(Cleaned_Data!$B$2:$B$315<EDATE(DATE(2024,9,1),1))*Cleaned_Data!$G$2:$G$315) -> 69376.88
A11: 2024-10 | B11: =SUMPRODUCT((Cleaned_Data!$B$2:$B$315>=DATE(2024,10,1))*(Cleaned_Data!$B$2:$B$315<EDATE(DATE(2024,10,1),1))*Cleaned_Data!$I$2:$I$315) -> 350281.26 | C11: =SUMPRODUCT((Cleaned_Data!$B$2:$B$315>=DATE(2024,10,1))*(Cleaned_Data!$B$2:$B$315<EDATE(DATE(2024,10,1),1))*Cleaned_Data!$G$2:$G$315) -> 58806.85
A12: 2024-11 | B12: =SUMPRODUCT((Cleaned_Data!$B$2:$B$315>=DATE(2024,11,1))*(Cleaned_Data!$B$2:$B$315<EDATE(DATE(2024,11,1),1))*Cleaned_Data!$I$2:$I$315) -> 493935.05 | C12: =SUMPRODUCT((Cleaned_Data!$B$2:$B$315>=DATE(2024,11,1))*(Cleaned_Data!$B$2:$B$315<EDATE(DATE(2024,11,1),1))*Cleaned_Data!$G$2:$G$315) -> 86179.15
A13: 2024-12 | B13: =SUMPRODUCT((Cleaned_Data!$B$2:$B$315>=DATE(2024,12,1))*(Cleaned_Data!$B$2:$B$315<EDATE(DATE(2024,12,1),1))*Cleaned_Data!$I$2:$I$315) -> 604824.01 | C13: =SUMPRODUCT((Cleaned_Data!$B$2:$B$315>=DATE(2024,12,1))*(Cleaned_Data!$B$2:$B$315<EDATE(DATE(2024,12,1),1))*Cleaned_Data!$G$2:$G$315) -> 103192.39
